<?xml version="1.0"?>
<robot name="humanoid_robot">

  <link name="base_link">
    <visual>
      <geometry>
        <box size="0.3 0.2 0.8"/>
      </geometry>
      <material name="grey">
        <color rgba="0.7 0.7 0.7 1"/>
      </material>
    </visual>
    <collision>
      <geometry>
        <box size="0.3 0.2 0.8"/>
      </geometry>
    </collision>
    <inertial>
      <mass value="20"/>
      <inertia ixx="1.37333333333" ixy="0" ixz="0" iyy="1.30666666667" iyz="0" izz="0.08333333333"/>
    </inertial>
  </link>

  <link name="left_arm_link1">
    <visual>
      <geometry>
        <cylinder length="0.4" radius="0.05"/>
      </geometry>
      <material name="blue">
        <color rgba="0.2 0.2 0.8 1"/>
      </material>
    </visual>
    <collision>
      <geometry>
        <cylinder length="0.4" radius="0.05"/>
      </geometry>
    </collision>
    <inertial>
      <mass value="2"/>
      <inertia ixx="0.01333333333" ixy="0" ixz="0" iyy="0.01333333333" iyz="0" izz="0.005"/>
    </inertial>
  </link>

  <joint name="left_shoulder" type="revolute">
    <parent link="base_link"/>
    <child link="left_arm_link1"/>
    <origin xyz="0.15 0 0.7" rpy="0 0 0"/>
    <axis xyz="0 1 0"/>
    <limit lower="-1.5708" upper="1.5708" effort="20" velocity="10"/>
  </joint>

  <link name="left_arm_link2">
    <visual>
      <geometry>
        <cylinder length="0.4" radius="0.05"/>
      </geometry>
      <material name="blue">
        <color rgba="0.2 0.2 0.8 1"/>
      </material>
    </visual>
    <collision>
      <geometry>
        <cylinder length="0.4" radius="0.05"/>
      </geometry>
    </collision>
    <inertial>
      <mass value="2"/>
      <inertia ixx="0.01333333333" ixy="0" ixz="0" iyy="0.01333333333" iyz="0" izz="0.005"/>
    </inertial>
  </link>

  <joint name="left_elbow" type="revolute">
    <parent link="left_arm_link1"/>
    <child link="left_arm_link2"/>
    <origin xyz="0 0 0.4" rpy="0 0 0"/>
    <axis xyz="0 1 0"/>
    <limit lower="-2.0944" upper="0" effort="20" velocity="10"/>
  </joint>

  <link name="right_arm_link1">
    <visual>
      <geometry>
        <cylinder length="0.4" radius="0.05"/>
      </geometry>
      <material name="red">
        <color rgba="0.8 0.2 0.2 1"/>
      </material>
    </visual>
    <collision>
      <geometry>
        <cylinder length="0.4" radius="0.05"/>
      </geometry>
    </collision>
    <inertial>
      <mass value="2"/>
      <inertia ixx="0.01333333333" ixy="0" ixz="0" iyy="0.01333333333" iyz="0" izz="0.005"/>
    </inertial>
  </link>

  <joint name="right_shoulder" type="revolute">
    <parent link="base_link"/>
    <child link="right_arm_link1"/>
    <origin xyz="-0.15 0 0.7" rpy="0 0 0"/>
    <axis xyz="0 1 0"/>
    <limit lower="-1.5708" upper="1.5708" effort="20" velocity="10"/>
  </joint>

  <link name="right_arm_link2">
    <visual>
      <geometry>
        <cylinder length="0.4" radius="0.05"/>
      </geometry>
      <material name="red">
        <color rgba="0.8 0.2 0.2 1"/>
      </material>
    </visual>
    <collision>
      <geometry>
        <cylinder length="0.4" radius="0.05"/>
      </geometry>
    </collision>
    <inertial>
      <mass value="2"/>
      <inertia ixx="0.01333333333" ixy="0" ixz="0" iyy="0.01333333333" iyz="0" izz="0.005"/>
    </inertial>
  </link>

  <joint name="right_elbow" type="revolute">
    <parent link="right_arm_link1"/>
    <child link="right_arm_link2"/>
    <origin xyz="0 0 0.4" rpy="0 0 0"/>
    <axis xyz="0 1 0"/>
    <limit lower="-2.0944" upper="0" effort="20" velocity="10"/>
  </joint>

</robot>
